<?xml version="1.0" ?>
<robot name="experiment">
  <mujoco>
    <compiler discardvisual="true" fusestatic="false" exactmeshinertia="false">

    </compiler>
  </mujoco>
  <link name="world"/>

  <joint name="digit_world" type="fixed">
    <origin xyz="0 0 0" rpy="0 -1.58 0"/>
    <parent link="world"/>
    <child link="baseLink"/>
  </joint>

  <joint name="table_world" type="fixed">
    <origin xyz="0 0 -0.25" rpy="0 0 0"/>
    <parent link="world"/>
    <child link="table__link"/>
  </joint>

  <joint name="obj_world" type="floating">
    <origin xyz="-0.02 0 0.5" rpy="0 0 0"/>
    <parent link="world"/>
    <child link="base_link"/>
  </joint>

  <link concave="yes" name="baseLink">
    <inertial>
      <origin rpy="0 0 0" xyz="0 0 0"/>
       <mass value=".1"/>
       <inertia ixx="1" ixy="0" ixz="0" iyy="1" iyz="0" izz="1"/>
    </inertial>
    <visual>
      <origin rpy="0 0 0" xyz="0 0 0"/>
      <geometry>
				<mesh filename="digit.STL" scale="1 1 1"/>
      </geometry>
       <material name="white">
        <color rgba="1 1 1 1"/>
      </material>
    </visual>
    <collision concave="yes">
      <origin rpy="0 0 0" xyz="0 0 0"/>
     <geometry>
				<mesh filename="digit.STL" scale="1 1 1"/>
      </geometry>
    </collision>
  </link>

  <link name="base_link">
    <contact>
      <rolling_friction value="0.001"/>
      <spinning_friction value="0.001"/>
    </contact>
    <inertial>
      <origin rpy="0 0 0" xyz="0 0 0"/>
       <mass value=".1"/>
       <inertia ixx="1" ixy="0" ixz="0" iyy="1" iyz="0" izz="1"/>
    </inertial>
    <visual>
      <origin rpy="0 0 0" xyz="0 0 0"/>
      <geometry>
        <mesh filename="textured_sphere_smooth.obj" scale="0.03 0.03 0.03"/>
      </geometry>
      <material name="white">
        <color rgba="1 1 1 1"/>
      </material>
    </visual>
    <collision>
      <origin rpy="0 0 0" xyz="0 0 0"/>
      <geometry>
	 <sphere radius="0.03"/>
      </geometry>
    </collision>
  </link>

  <link name="table__link">
    <collision name="table__collision">
      <origin xyz="0 0 0" rpy="0 0 0" />
      <geometry>
        <box size="0.75 0.5 0.5"/>
      </geometry>
    </collision>
    <visual name="table__visual">
      <origin xyz="0 0 0" rpy="0 0 0" />
      <geometry>
        <box size="0.75 0.5 0.5"/>
      </geometry>
    </visual>
  </link>
</robot>
